Workbook
Name __Res1: #REF!
Name _MailOriginal: Notifications!$I$11
Name _Res1: #REF!
Name _sam2: '[1]Validate '!#REF!
Name BF_Analytics: #REF!
Name comm1: #REF!
Name comm2: #REF!
Name comm3: #REF!
Name comm4: #REF!
Name core: #REF!
Name core1: '[2]Voyager Services Proposal'!$A$466
Name corp: '[3]Project Scope'!#REF!
Name corpend: '[3]Project Scope'!#REF!
Name dnrTaskList: OFFSET('[4]Sys Config'!$G$13,,,COUNTA('[4]Sys Config'!$G$13:$G$65536),1)
Name duration: #REF!
Name duration2: #REF!
Name endnew: '[5]Project Scope'!#REF!
Name enduser: #REF!
Name functionality: #REF!
Name IA_Analytics: #REF!
Name interface: #N/A
Name interfaces: #REF!
Name new: '[5]Project Scope'!#REF!
Name no: '[5]Project Scope'!#REF!
Name nonew: '[5]Project Scope'!#REF!
Name not: '[3]Project Scope'!#REF!
Name notcorp: '[3]Project Scope'!#REF!
Name pilot: #REF!
Name ProjectDuration: #REF!
Name reports: #REF!
Name Review_Commercial_Analytics___Property___Rent_Roll: #REF!
Name rpt: #REF!
Name sam: '[3]Project Scope'!#REF!
Name Split: #REF!
Name Test: #REF!
Name totrpts: #REF!
Name users: [6]Assumptions!$C$19
Name validate2: '[1]Validate '!#REF!

Sheet KPI
F1: Received Status | G1: (Multiple Items)
F3: Count of Sr.No. | G3: Column Labels
F4: Departments | G4: Grand Total
F5: Grand Total
F16: Count of Sr.No. | G16: Column Labels
F17: Departments | G17: (blank) | H17: Grand Total
F18: Finance | G18: 14 | H18: 14
F19: Procurement | G19: 19 | H19: 19
F20: Grand Total | G20: 33 | H20: 33
J24: =32/82 -> 0.3902439

Sheet RFI Index
A1: XX
A2: Request for Information
A3: Sr.No. | B3: Yardi Module | C3: BPR Reference | D3: Requirements (What we want?) | E3: Department | F3: Priority | G3: Project Team Member | H3: Shared Date | I3: Target Date | J3: Received Status | K3: Received Date | L3: Remarks | M3: Closure remarks | N3: Delayed Days | O3: Dependency | P3: Configured in Live
A4: 1 | B4: Vendor Café | C4: P2P3 | D4: Vendor Markets | E4: Procurement | F4: High
A5: =A4+1 -> 2 | B5: Vendor Café | C5: P2P4, P2P5 | D5: Vendor Categories and Insurance Types | E5: Procurement | F5: High
A6: =A5+1 -> 3 | B6: Vendor Café | C6: P2P6,P2P8 | D6: Vendor Workflow | E6: Procurement | F6: Critical
A7: =A6+1 -> 4 | B7: Vendor Café | C7: P2P7 | D7: Mandatory documents for Vendor Registration | E7: Procurement | F7: Low
A8: =A7+1 -> 5 | B8: Vendor Café | C8: P2P14 | D8: Vendor User Defined Field | E8: Procurement | F8: High
A9: =A8+1 -> 6 | B9: Vendor Café | C9: P2P15 | D9: Vendor Agreement | E9: Procurement | F9: Low
A10: =A9+1 -> 7 | B10: Vendor Café | C10: P2P16 | D10: Vendor Cafe configurations | E10: Procurement | F10: Low
A11: =A10+1 -> 8 | B11: Vendor Café | C11: P2P17 | D11: VC Email Templates | E11: Procurement | F11: Low
A12: =A11+1 -> 9 | B12: Vendor Café | C12: P2P19 | D12: Support numbers/email | E12: Procurement | F12: High
A13: =A12+1 -> 10 | B13: Vendor Café | D13: EFT Format | E13: Finance | F13: Low
A14: =A13+1 -> 11 | B14: P2P | C14: AP1.1 | D14: Person creating PO | E14: Procurement | F14: High
A15: =A14+1 -> 12 | B15: P2P | C15: AP1.1 | D15: Person creating Invoice | E15: Finance | F15: High
A16: =A15+1 -> 13 | B16: P2P | C16: AP1.3 | D16: Provide a list of Expense types | E16: Procurement | F16: Critical
A17: =A16+1 -> 14 | B17: P2P | C17: AP1.4 | D17: PR and PO Approval Workflow | E17: Procurement | F17: Critical
A18: =A17+1 -> 15 | B18: P2P | C18: AP1.5 | D18: PO attachment types | E18: Procurement | F18: High
A19: =A18+1 -> 16 | B19: P2P | C19: AP1.6 | D19: Invoice approval DOA | E19: Finance | F19: Critical
A20: =A19+1 -> 17 | B20: P2P | C20: AP1.7 | D20: Invoice Attachment types | E20: Finance | F20: High
A21: =A20+1 -> 18 | B21: P2P | C21: AP1.10 | D21: Direct Payable attachment types | E21: Finance | F21: High
A22: =A21+1 -> 19 | B22: P2P | C22: AP1.11 | D22: Fields for EFT to be captured on bank record | E22: Finance | F22: High
A23: =A22+1 -> 20 | B23: P2P | C23: AP1.11 | D23: Invoice Payment Methods | E23: Finance | F23: High
A24: =A23+1 -> 21 | B24: P2P | C24: AP1.12 | D24: Payments approval DOA (GL Disbursment) | E24: Finance | F24: Critical
A25: =A24+1 -> 22 | B25: P2P | C25: AP1.13 | D25: Payment Attachment types | E25: Finance | F25: High
... A27: =A26+1 -> 24 | B27: P2P | C27: Additional Notes | D27: Terms and Conditions to printed on PO - Static Field | E27: Procurement | F27: High
A28: =A27+1 -> 25 | B28: P2P | D28: PO User Defined Fields | E28: Procurement | F28: High
A29: =A28+1 -> 26 | B29: P2P Services | C29: AP4.2 | D29: Service Contract DoA | E29: Procurement | F29: Critical
A30: =A29+1 -> 27 | B30: P2P Services | D30: Service Contract Business | E30: Procurement | F30: High
A31: =A30+1 -> 28 | B31: P2P Services | C31: AP4.3 | D31: Service Contract Attachments | E31: Procurement | F31: High
A32: =A31+1 -> 29 | B32: Fixed Assets | C32: FA2 | D32: Asset Group | E32: Finance | F32: High
A33: =A32+1 -> 30 | B33: Fixed Assets | C33: FA3 | D33: Asset Types | E33: Finance | F33: High
A34: =A33+1 -> 31 | B34: Fixed Assets | C34: FA4 | D34: Asset Depreciation Groups | E34: Finance | F34: High
A35: =A34+1 -> 32 | B35: Fixed Assets | C35: FA13 | D35: Fixed Asset Attachments | E35: Finance | F35: High
A36: =A35+1 -> 33 | B36: Fixed Assets | D36: Asset Process | E36: Finance | F36: High
A37: =A36+1 -> 34 | B37: Facility Manager | C37: FM1 | D37: Maintenance Models | E37: Facility Management
A38: =A37+1 -> 35 | B38: Facility Manager | C38: FM2 | D38: Team Structure | E38: Facility Management
A39: =A38+1 -> 36 | B39: Facility Manager | C39: FM3 | D39: Employee Time slots | E39: Facility Management
A40: =A39+1 -> 37 | B40: Facility Manager | C40: FM8, FM9 | D40: WO Priority | E40: Facility Management
A41: =A40+1 -> 38 | B41: Facility Manager | C41: FM10, FM11 | D41: WO Status and Change Reason | E41: Facility Management
...

Sheet Sheet1
A1: Requirements (What we want?) | B1: Received Status
A2: Guest Template | B2: =VLOOKUP(A2,'RFI Index'!D:J,7,0) -> #N/A | D2: Rent - Car Parking - Guest Template / SRS?
A3: Applicant/Tenant Charge Fees Matrix | B3: =VLOOKUP(A3,'RFI Index'!D:J,7,0) -> #N/A
A4: Tenant Service requests and DOA | B4: =VLOOKUP(A4,'RFI Index'!D:J,7,0) -> #N/A
A5: Chart of Accounts (COA) | B5: =VLOOKUP(A5,'RFI Index'!D:J,7,0) -> #N/A
A6: Charge codes | B6: =VLOOKUP(A6,'RFI Index'!D:J,7,0) -> #N/A
A7: BD Workflows - Approving LL leads (Service request) | B7: =VLOOKUP(A7,'RFI Index'!D:J,7,0) -> #N/A
A8: Attachment Types under this process | B8: =VLOOKUP(A8,'RFI Index'!D:J,7,0) -> #N/A
A9: BD Workflows - APproving Head leases (Amendment WF) | B9: =VLOOKUP(A9,'RFI Index'!D:J,7,0) -> #N/A
A10: Charge codes for head lease | B10: =VLOOKUP(A10,'RFI Index'!D:J,7,0) -> #N/A
A11: Lease Type for head lease | B11: =VLOOKUP(A11,'RFI Index'!D:J,7,0) -> #N/A
A12: Type of activites to be tracked at headlease proposal | B12: =VLOOKUP(A12,'RFI Index'!D:J,7,0) -> #N/A
A13: Requirements for lessee accounting - GL accounts, etc. | B13: =VLOOKUP(A13,'RFI Index'!D:J,7,0) -> #N/A
A14: Holdover process for Head Lease | B14: =VLOOKUP(A14,'RFI Index'!D:J,7,0) -> #N/A
... A33: Legal Notifications | B33: =VLOOKUP(A33,'RFI Index'!D:J,7,0) -> #N/A

Sheet Notifications
A1: Return
A2: To be taken from AIM (Still under development)
A4: BPR Ref # | B4: Yardi Template Reference | C4: Entity | D4: Property | E4: Process Name | F4: Notification Description | G4: Recipients | H4: When to send notifications? Trigger | I4: Email Format | J4: SMS Format

Sheet Takeover-Scenarios
A1: Return
C2: Managed Properties | D2: Investment Properties
A3: 1 | B3: Pending Renewals of Tenants as of Take-over Date
A4: 2 | B4: Commercial Tenants - All scenarios for commercial tenants with VAT & along with treatment for Investment properties and managed properties. This should be based on all types for invoicing frequency – Annual, Half yearly, Quarterly etc.
A8: LL Handover Scenario
A9: Project Profitablity Report : - Customization
A10: Income/Expenses report apportioned based on Head Lease LL contract Period esp in days.
A11: This is required for Property profitability analysis as the LL Management contract renewal is based on the same.
A12: This is required only for the reporting purpose for decision making for future renewals of head leases.
A14: In case of Investment properties, the requirement is to review the complete profitability after considering the head lease expenses/AMCs/Other expenses and income from subleases (Rent, Admin other income) for decision making for renewals etc.
A15: Example :
A16: Head Lease Period - 08-July-2023 to 07-Aug-2024
A17: Sublease period - 15-Sept-2023 to 14-Sept-2024.
A18: In this case Driven would require the details to identify the full revenue/expenses recognized for the investment property till end date of the head lease contract i.e. LL Handover date only i.e. 07-Aug-2024.

Sheet Takeover-Tenant Settlement
A1: Return
A4: 1 | B4: Tenant Settlement document Samples/Format with possible scenarios.

Sheet Tenant Handover settlement-scen
A3: Scenario -1
A4: Investment properties
A5: Cut-off | B5: 45169
A6: Tenant -1 | E6: Reponsibility | G6: Remarks
A7: Rent -1 | B7: 45078 | C7: 20000 | D7: Cleared | E7: Driven
A8: Rent -2 | B8: 45139 | C8: 20000 | D8: Cheque bounced | E8: Driven | F8: Aug-Sept | G8: Overlapping Period
D9: Tenant Pays to Driven | F9: 20000 | G9: Driven will keep 10k & handover 10k to LL
D10: Tenant Pays to LL | G10: LL will handover 10k for Aug to Driven
D11: Legal Case
A12: Rent -3 | B12: 45200 | C12: 20000 | D12: Cheque bounced | E12: LL

Sheet PMA Renewals
A3: Driven - LL Agreement Renewals (Change in Agreement Type)
A5: 1 | B5: Managed Property to Investment property
B6: Tenant Security Deposit - Held in LL bank | C6: LL to handover to Driven
B7: Tenant Security Deposit - Held in Driven Bank | C7: LL to agree tranfer of SD in to Driven Name
B8: Tenant O/s in managed property as of cut-off date
B9: Tenant advances in managed property as of cut-off date
A12: 2 | B12: Investment property to Managed Property
B13: Tenant Security Deposit
B14: Tenant O/s in managed property as of cut-off date
B15: Tenant advances in managed property as of cut-off date
A17: 3 | B17: Managed Property to Managed Property
B18: PM fees % change
B19: PM Fees calculation methods | C19: New Fee pool based on newly agreed terms to be created & Mapped to Property
A21: 4 | B21: Investment property to Investment Property
B22: Change in Rent Remuneration to LL | C22: Renewal to be processed for Head lease in system.
B23: Some time negotiation is still in process after contract expiry, Driven would be recognizing the rent exps based on earlier contract. | C23: 1. Check if Rent exps calculation can be generated from system. 2. JE with reverse next month would be entered to book Rental exps.

Sheet Vendor Markets
A1: Return
A2: Sr.no. | B2: Markets
A3: 1 | B3: Local
A4: 2 | B4: International

Sheet Vendor Cat & Ins
B1: Return
B3: Vendor Categories and Insurance
B4: Category Name | C4: Insurance Setup | D4: Consultant Comments
B6: Supplier Goods & Services | D6: Added to Master DB
B7: Contractor | C7: Third-Party Liability, Workers' Compensation/ Employers' Liability, Contractors' All Risk (CAR) Insurance | D7: Added to Master DB
B8: Authority | D8: Added to Master DB
B9: Internal / One time vendor | D9: Added to Master DB
B15: Insurance Setup
B16: Insurance type | C16: Consultant Comments
B17: Third-Party Liability
B18: Workers' Compensation/ Employers' Liability
B19: Contractors' All Risk (CAR) Insurance
B25: ADCG
B26: Imkan | C26: Real Estate Development Business
B27: Imkan Estates | C27: Shared services for anything related to Imkan
B28: Asseto | C28: Property Management | D28: Manages both commercial and residential
B30: Accounting

Sheet Bank Structure
D5: Asseto estate | F5: Imkan P1 (only commercial) | G5: ADCG P1 (Residential and Commercial)
C6: Budget | D6: Opex
E7: Vehicles | F7: Service charges | G7: Community charges
E8: FF&F | F8: Marketing Expenses | G8: Marketing Expenses
E9: IT | F9: Legal fees | G9: Legal fees
E10: Payroll | F10: Leasing Consultancy and RDD
E11: Shared Services (Legal, Marketing etc.)
D12: Capex
E22: Entity | F22: GL Account | G22: Dr | H22: Cr
E23: Baniyas Tower | F23: AMC Cost | G23: 2000
F24: AP | H24: 2000

Sheet WF for Vendors
A1: Return
A2: Vendor Workflow (DOA)
A4: Category: | B4: All Categories
A6: Sr No. | B6: Object | C6: Process Name | D6: Step No. | E6: Workflow Step | F6: Responsible Role | G6: Next Step | H6: Modification Step | I6: Completion Step | J6: Rejection Step | K6: KPI-Completion Days
A7: 1 | B7: Vendor | C7: Vendor Approval | D7: 1 | E7: New Vendor | F7: Procurement officer | G7: Finance Review
F8: AP Accountant
D10: 2 | E10: Finance Review | F10: Finance Manager | G10: Approved
F11: AP Accountant | G11: Rejected
G12: Modifications Required
D14: 3 | E14: Approved | I14: Yes
D15: 4 | E15: Rejected | J15: Yes
D16: 5 | E16: Modifications Required | H16: Yes
E18: Originator not to be final approval
A21: Consultant Comments | B21: Added to Master DB

Sheet Vendor Attachment types
A1: Return
A6: Sr No | B6: Object Name | C6: Attachment Type | D6: Mandatory | E6: Consultant Comments
A8: 1 | B8: Vendor | C8: Trade License | D8: Yes | E8: Added to Master DB
A9: 2 | B9: Vendor | C9: Tax Certificate | D9: Yes | E9: Added to Master DB
A10: 3 | B10: Vendor | C10: Complete Company Profile/Brochure | E10: Added to Master DB
A11: 4 | B11: Vendor | C11: Bank Details Letter | D11: Yes | E11: Added to Master DB
A12: 5 | B12: Vendor | C12: Emirates ID | E12: Added to Master DB
A13: 6 | B13: Vendor | C13: POA | E13: Added to Master DB
A14: 7 | B14: Vendor | C14: Management Sys. Certificate | E14: Added to Master DB
A15: 8 | B15: Vendor | C15: Financial Statement | E15: Added to Master DB
A16: 9 | B16: Vendor | C16: Supplier Code of Conduct | E16: Added to Master DB
A17: 10 | B17: Vendor | C17: Vendor Registration Form | E17: Added to Master DB
A18: 11 | B18: Vendor | C18: Non Disclosure Agreement | E18: Added to Master DB
A19: 12 | B19: Vendor | C19: COI | D19: Yes | E19: Added to Master DB

Sheet Vendor UDFs
A1: Return
A3: # | B3: Vendor User Defined fields | C3: Field Format (Date/Text/List values/Number) | D3: Mandatory | E3: Consultant Comments
A4: 1 | B4: Vendor Category | C4: Goods, Services, Consultant, AMC, Contractor | D4: ✅ Mandatory | E4: Added to Master DB
A5: 2 | B5: Trade License name | C5: Text | D5: ✅ Mandatory
A6: 3 | B6: Trade License # | C6: Text | D6: ✅ Mandatory
A7: 4 | B7: Trade License Expiry | C7: Date | D7: ✅ Mandatory
A8: 5 | B8: VAT Certificate Expiry | C8: Date | D8: ✅ Mandatory
A9: 6 | B9: Authorized Signatory Name | C9: Text | D9: ✅ Mandatory
A10: 7 | B10: Type of Entity/Tax Classification | C10: List (Free Zone^Government^Main Land) | D10: Optional

Sheet Vendor Agreement
A1: Return
A2: Vendor Agreement
A3: Below is the standard agremeent in Yardi:
A4: Vendor agreement can be configured based on Legal requirements. (Max length: 5000 characters)
B6: You ("Vendor") have requested that Nasser Abdulla Hussain Lootah and/or its subsidiaries or affiliates (collectively "Client") consider purchase of Vendor's products or services. Vendor agrees that, as a condition of this Agreement, it will keep registration current at all times. Vendor further understands and agrees that it will provide proof of insurance as required by Client, including naming Client as an additional insured on Vendor's general liability policy. The proof of insurance required will be based on Vendor's stated industry code and identified location of operation. Vendor agrees to indemnify and hold harmless Client(i) from any damage, claim, or loss arising out of Vendor's inaccurate statement or choice of industry code and/or identified location of operation and (ii) if any employee of Vendor, or independent contractor hired by Vendor, suffers a work-related injury or illness and makes a claim against Client. This Agreement does not reduce any obligation Vendor has or may have under any other written agreement with Client nor does it constitute an obligation by Client to actually engage Vendor or purchase its products or services.

Sheet VC configurations
A1: Return
B2: Key Configurations are highlighted in yellow.
B3: Non highlighted rows are recommended standard configurations
B5: Description | C5: Value
B6: Dashboard
B7: Approved Invoices Tab Required | C7: Yes
B8: Default Time Interval in Search Filters | C8: 365
B9: Maximum Time Interval Allowed for Search Filters | C9: 365
B10: Messages Count Required | C10: Yes
B11: Not Submitted Invoices Tab Required | C11: Yes
B12: Paid Invoices Tab Required | C12: Yes
B13: Pending Invoices Tab Required | C13: Yes
B14: Purchase Orders Tab Required | C14: Yes
B15: Rejected Invoices Count Required | C15: Yes
B16: Service Contract Tab Required | C16: Yes
B17: Vendor Ledger Tab Required | C17: Yes
B18: Invoice Processing
B19: Allow Deletion of Line Items on Invoice Screen | C19: No
B20: Allow Duplicate Invoice No. | C20: No
B21: Allow Invoice Amount Greater Than PO Amount | C21: No
B22: Allow Invoice Line Item Amount Greater than PO Line Item Amount | C22: No
B23: Allow Invoicing Against Received POs Only | C23: Yes
B24: Allow PDF Image Upload on Data Invoice | C24: Mandatory
B25: Inactive Property Alert Message | C25: This property no longer accepts invoice uploads after [insert property handover date + 60days] due to a sale or change in property management. Please contact the new property management company directly for guidance on submitting invoices.
B26: Invoice Description Mandatory | C26: Yes
B27: PO Mandatory | C27: No
B28: Post Invoice to Voyager as | C28: Invoice
B29: Show Credit option in Invoice Type selection | C29: Yes
B30: Show Invoice Due Date | C30: Yes
... B32: Show Upload PDF Invoice Tab | C32: Yes
B33: Profile
B34: Allow Multiple International EFT Setup | C34: Yes
B35: Document Mandatory On Insurance Information Tab | C35: No
B36: Documents Required | C36: Mandatory
B37: Editable Market | C37: No
B38: Get Contact Types From Voyager | C38: No
B39: Markets Required | C39: Yes
B40: Maximum Vendor Document Upload Size In MB | C40: 30
B41: Show EFT Tab in Vendor Profile | C41: Yes
B42: Show Insurance Tab in Vendor Profile | C42: Yes
...

Sheet VC Email Templates
A1: Return
B4: Sr.No | C4: Email Template Name | D4: Email Trigger Description | E4: Template
B5: 1 | C5: EFT data submitted notification template 1 | D5: EFT_DATA_SUBMITTED_NOTIFICATION | E5: Your Electronic File Transfer (EFT) has been successfully submitted through the Vendor Portal. The submission will now be reviewed by the Avison Young Procurement Team. You will receive a further notification once the review is complete. Submission Details: Vendor Name: [Vendor_Name] Submission ID: [EFT_Reference_ID] Submission Date: [Date_Timestamp] No further action is required at this time. For questions or support, please contact Procurement Support Email
B6: 2 | C6: EFT rejected template 1 | D6: EFT_REJECTED_NOTIFICATION | E6: Your Electronic File Transfer (EFT) submission has been reviewed and rejected by the Avison Young Procurement Team. Reason for Rejection: [Insert specific reason, e.g., "Missing mandatory supporting documentation" or "Incorrect PO reference number"] Please review the details, make the necessary corrections, and resubmit your EFT file through the Vendor Portal. If you require further guidance, please contact the Procurement Team at Procurement Support Email
B7: 3 | C7: Registration Done Notification Template 1 | D7: REGISTRATION_DONE_NOTIFICATION | E7: Thank you for completing your registration on the Avison Young Vendor Portal. Your account has been successfully created and is now under review by the Procurement Team. You will be notified once your registration has been approved and access is fully enabled. Registration Details: Vendor Name: [Vendor_Name] Registration ID: [Registration_ID] Submission Date: [Date_Timestamp] If you have any questions or need assistance, please contact us at Procurement Support Email
B8: 4 | C8: Registration Invite Template 1 | D8: VENDOR_REGISTRATION_INVITE | E8: You have been invited to register as a vendor with Avison Young via our Vendor Portal. To begin the registration process, please follow the link below and complete the required information: [Registration_Link] Instructions: Complete your company profile and banking information Upload any required compliance documents Submit your registration for review Once submitted, your application will be reviewed by the Avison Young Procurement Team. You will be notified upon approval. If you have any questions or require assistance, please contact us at Procurement Support Email
B9: 5 | C9: User Activation Notification Template 1 | D9: USER_ACTIVATION_NOTIFICATION | E9: Your user account for the Avison Young Vendor Portal has been successfully activated. You may now log in and begin using the system to manage your vendor profile, submit invoices and credit notes, and track purchase orders and other procurement activities. Account Details: User Name: [User_Name] Email: [User_Email] Activation Date: [Activation_Timestamp] Portal Access: [Vendor_Portal_URL] If you have any questions or require support, please contact the Procurement Team at Procurement Support Email We’re glad to have you on board.

Sheet VC Support emails
A1: Return
A3: Support Information to be displayed to vendor in Vendor Café
A5: Type | B5: Information
A6: Phone number
A7: Email

Sheet Vendor EFT format
A2: Return
B5: Fields | C5: Mandatory(Yes/No)
B6: Beneficiary Name | C6: Yes
B7: Bank Name | C7: Yes
B8: IBAN | C8: Yes
B9: Account Number | C9: Yes
B10: Branch Name | C10: Yes
B11: Swift code | C11: Yes
B15: Consultant Comments | C15: Configured on Master DB

Sheet Person creation PO
A1: Return
A3: Person creating Purchase Order in the system:
A4: Still no separate team for procurement team
A7: Sr No | B7: Legal Entity | C7: Property | D7: Role | E7: Task
A8: 1 | B8: All | C8: All Properties | D8: FM Manager | E8: PR Creation
D9: Document Control
D10: PM Admin
A11: 2 | B11: All | C11: All Properties | D11: FM Manager | E11: PO Creation
D12: FM Manager
D13: Document Control
D14: PM Admin
A15: 3 | B15: All | C15: All Properties | D15: FM Technician | E15: GRN
A18: 4 | B18: All | C18: All Properties | E18: Create PR via PO

Sheet Person Creating Invoice
A1: Return
A4: Sr No | B4: Legal Entity | C4: Property | D4: Role | E4: Purpose
A5: 1 | B5: All | C5: All | D5: AP accountant | E5: Elevate - All invoices
A6: 2 | B6: All | C6: All | D6: Vendor | E6: Vendor Café
A7: 3 | B7: All | C7: All | D7: FM Manager | E7: Person doing GRN

Sheet Expense Type
B1: Return
B3: Expense types | C3: Consultant Comments
B4: Legal
B5: Security
B6: Facility Management
B7: Insurance
B8: Utilities
B9: Service Charge
B10: Admin
B11: IT
B12: Marketing
B13: HR
B14: Property Management
B15: Authoritiy Fees
B16: Service Contract

Sheet PO Approval DOA
A1: Return | F1: Consultant Comments | G1: Added to Master DB
A3: Expense type: All
A5: Sr No. | B5: Object | C5: Process Name | D5: Step No. | E5: Workflow Step | F5: Responsible Role | G5: Next Step | H5: Amount From | I5: Amount To | J5: Modification Step | K5: Rejection Step | L5: Completion Step
A6: 1 | B6: Purchase Order | C6: Core_PR/PO | D6: 1 | E6: New PR | F6: PM Admin | G6: PR - PM Manager Approval | H6: 0 | I6: 2999.99
F7: PM Admin | G7: PR - Landlord Approval | H7: 3000 | I7: 999999
F8: Requester
D9: 2 | E9: PR - Landlord Approval | F9: Asset Manager | G9: PR - PM Manager Approval
G10: Reject
G11: Modification Required
D12: 3 | E12: PR - PM Manager Approval | F12: PM Manager | G12: PO - GM Approval
G13: PO - Finance Review
G14: PO - Finance Review
G15: Reject
G16: Modification Required
D18: 4 | E18: PO - GM Approval | F18: General Manager | G18: PO - Finance Review
G19: Rejected
G20: PO - Modification Required
D22: 5 | E22: PO - Finance Review | F22: Finance Manager | G22: Approved
G23: Rejected
G24: PO - Modification Required
D26: 6 | E26: PO - XX Approval | F26: XX | G26: XX
G27: XX
G28: Rejected
G29: PO - Modification Required
D31: 6 | E31: PO - XX Approval | F31: XX | G31: XX
G32: XX
G33: Rejected
G34: PO - Modification Required
D35: 7 | E35: Approved | L35: Yes
D36: 8 | E36: Rejected | K36: Yes
D37: 9 | E37: PO - Modification Required | F37: Procurement Officer | G37: PO - Procurement Manager Approval | J37: Yes
A39: Expense type: Other Expenses
A41: Sr No. | B41: Object | C41: Process Name | D41: Step No. | E41: Workflow Step | F41: Responsible Role | G41: Next Step | H41: Amount From | I41: Amount To | J41: Modification Step | K41: Rejection Step | L41: Completion Step
A42: 1 | B42: Purchase Order | C42: Core_PR/PO | D42: 1 | E42: New PR | F42: Admin | G42: PR - Department Manager Approval
F43: Requester
D45: 2 | E45: PR - Department Manager Approval | F45: Marketing Manager | G45: PO - Finance Review
F46: IT Manager | G46: PO - Finance Review
F47: Admin Manager | G47: PO - Finance Review
G48: Reject
G49: Modification Required
...

Sheet Invoice Approval DOA
A1: Return | E1: Consultant Comments | F1: Added to Master DB
A2: Expense type: Facilities
A3: Sr No. | B3: Object | C3: Process Name | D3: Step No. | E3: Workflow Step | F3: Responsible Role | G3: Next Step | J3: Modification Step | K3: Rejection Step
A4: 1 | B4: Invoice Register | C4: Invoice approval | D4: 1 | E4: Add invoice | F4: Accountant | G4: Send for Fianance Review
D5: 2 | G5: Modify invoice
G6: Reject Invoice
D8: 3 | E8: Send for Finance Review | F8: Finance Manager | G8: Approve Invoice
G9: Modify invoice
G10: Reject Invoice
F11: Finance Manager | G11: Approve Invoice
G12: Modify invoice
G13: Reject Invoice
D14: 4 | E14: Approve Invoice | G14: Approved
D15: 5 | E15: Modify invoice | F15: Accountant | G15: Review invoice | J15: Yes
D16: 6 | E16: Reject Invoice | F16: Accountant | G16: Rejected
A18: Expense type: All
A19: Sr No. | B19: Object | C19: Process Name | D19: Step No. | E19: Workflow Step | F19: Responsible Role | G19: Next Step | H19: Amount From | I19: Amount To | J19: Modification Step | K19: Rejection Step | L19: Completion Step | M19: KPI-Completion Days
A20: 1 | B20: Invoice Register | C20: Invoice approval | D20: 1 | E20: New Invoice | F20: AP Accountant | G20: Finance Manager Review
F21: Vendor Café | G21: Finance Manager Review
F22: Originator | G22: Finance Manager Review
D23: 2 | E23: Finance Manager Review | F23: Finance Manager | G23: Approved
G24: Rejected
G25: Modification Required
D26: 3 | E26: Approved | L26: Yes
D27: 4 | E27: Rejected | K27: Yes
D28: 5 | E28: Modification Required | F28: AP Accountant | G28: Finance Manager Review | J28: Yes

Sheet Bank EFT
A1: Return | B1: 7
A2: Bank Accounts
A4: Information to be captured on bank account(client's, Vendor's, Tenant's)
A5: Add fields that are required as per business requirements
A7: Fields | B7: Mandatory(Yes/No)
A8: Beneficiary Name | B8: Yes
A9: Beneficiary Address 1 | B9: Yes
A10: IBAN | B10: Yes
A11: Beneficiary Bank Name | B11: Yes
A12: Beneficiary Bank Address 1 | B12: Yes
A13: Swift code | B13: Yes
A14: Account Number | B14: Yes

Sheet Payment Approval
A1: Return
A2: Expense Type: Gldisbu.
A3: Sr No. | B3: Object | C3: Process Name | D3: Step No. | E3: Workflow Step | F3: Responsible Role | G3: Next Step | H3: Modification Step | I3: Rejection Step | J3: Completion Step | K3: KPI-Completion (Days)
A4: 1 | C4: Service Contract | D4: 1 | E4: New Service Contract | F4: FM Manager | G4: General Manager Approval
D7: 2 | E7: General Manager Approval | F7: General Manager | G7: Finance Review
G8: Reject
G9: Modification Required
D11: 3 | E11: Finance Review | F11: Fianance Manager | G11: Approve
G12: Modification Required
D13: 4 | E13: Approved | J13: Yes
D14: 5 | E14: Rejected | I14: Yes
D15: 6 | E15: Modification Required | F15: FM Manager | G15: General Manager Approval | H15: Yes

Sheet Payment methods
A1: Return
A3: Payment methods to Vendors
A4: Sr No | B4: Method
A5: 1 | B5: Cheque
A6: 2 | B6: Cash
A7: 3 | B7: EFT
A8: 4 | B8: Bank Transfer
A9: 5 | B9: Credit Card
A10: 6 | B10: Noqodi

Sheet P2P Attachment type
A1: Return
A2: Sr No | B2: Object Name | C2: Attachment Type | D2: Consultant Comments
A3: 1 | B3: Purchase Order | C3: Delivery note | D3: Added to Master DB
A4: 2 | B4: Purchase Order | C4: Quotation | D4: Added to Master DB
A5: 3 | B5: Purchase Order | C5: Comparsion sheet (CS) | D5: Added to Master DB
A6: 4 | B6: Purchase Order | C6: Maintenance Technical Report | D6: Added to Master DB
A7: 5 | B7: Purchase Order | C7: Other | D7: Added to Master DB
A8: 6 | B8: Purchase Order | C8: Job Completion Report | D8: Added to Master DB
A9: 7 | B9: Purchase Order | C9: Security Deposit docs | D9: Added to Master DB
A10: 8 | B10: Purchase Order | C10: Move in Report | D10: Added to Master DB
A11: 9 | B11: Purchase Order | C11: Tax Invoice | D11: Added to Master DB
A12: 10 | B12: Purchase Order | C12: Photo Proof | D12: Added to Master DB
A13: 11 | B13: Service Contract | C13: Job Completion Report | D13: Added to Master DB
A14: 12 | B14: Service Contract | C14: Signed Service Contract | D14: Added to Master DB
... A24: 22 | B24: Payable | C24: Job Completion Report | D24: Added to Master DB

Sheet Cancel PO
A1: Return
A4: Please explain process for Cancelling PO (See below) | B4: Finance Comments
A7: Scenario 1: PO under Workflow Approval
A8: If PO needs to be cancelled, then the same should be Rejected using the WF Rejection step | B8: Procurement Officer can conduct this if he has the necessary approvals
A10: Scenario 2: PO Approved. No Material to be received
A11: Short Close PO using the PO Close functionality | B11: All PO cancellation /Modification / any change should be with Procurement
A13: Scenario 3: PO Approved. Partial Material to be received
A14: Perform GRN, Invoice, Payment for the Partial Quantity
A15: Short Close PO using the PO Close functionality. In this case the remaining Material will not be available for further processing | B15: Full goods or services not received therefore po partially cancelled

Sheet PO T&Cs
A1: Return
A3: Purchase Order Terms and Conditions:
A4: This is static field which will be printed on all Pos across the system

Sheet PO UDF
A1: Return
A3: PO User Defined fields | B3: Field Format (Date/Text/List values/Number) | C3: Print in PO Template
A4: Requester | B4: Text | C4: No
A5: Buyer | B5: Text | C5: Yes
A6: Attention To | B6: Text | C6: Yes
A7: Payment Terms | B7: List (Advance^7 Days^30 Days^45 Days^60 Days^100% After Completion^Other) | C7: Yes
A8: Quotation Ref# | B8: Text | C8: Yes
A9: Quotation Date | B9: Text | C9: No
A22: Maximum 14 fields

Sheet Service contract DOA
A1: Return
A2: Expense Type: Service Contract
A3: Sr No. | B3: Object | C3: Process Name | D3: Step No. | E3: Workflow Step | F3: Responsible Role | G3: Next Step | H3: Modification Step | I3: Rejection Step | J3: Completion Step | K3: KPI-Completion (Days)
A4: 1 | B4: Service Contract | C4: Service Contract | D4: 1 | E4: New Service Contract | F4: FM Manager | G4: General Manager Approval
D7: 2 | E7: General Manager Approval | F7: General Manager | G7: Finance Review
G8: Reject
G9: Modification Required
D11: 3 | E11: Finance Review | F11: Fianance Manager | G11: Approve
G12: Modification Required
D13: 4 | E13: Approved | J13: Yes
D14: 5 | E14: Rejected | I14: Yes
D15: 6 | E15: Modification Required | F15: FM Manager | G15: General Manager Approval | H15: Yes

Sheet Service Contract Trade
A1: Return
B3: Service Category
B4: TFM
B5: Security
B6: Speaclized & Others
A8: For AMCs, PO accrual will be run for all eligible POs irrespective of GRN
A10: PO Deductions
A11: Date | B11: Description | C11: Deduction Reason | D11: Amount

Sheet Prepay Mapping
A1: Return
A3: Prepay mapping to be done against one prepaid expense GL account
A5: From GL Account Code | B5: To GL Account Code | C5: Mapping Account
A6: This is Expense GL Account | B6: This is Expense GL Account | C6: Asset Account for prepaid expenses deferment. | D6: Prepaid Exps GL description

Sheet Asset group
A1: Return
B2: Groups of Assets in case sub Asset types grouping is required , Asset group is used only for analytics and reporting
A5: Asset group Code | B5: Asset Group name | C5: Description | D5: Finance | E5: FM
A6: HVACMec | B6: HVACMec | C6: HVACMec
A7: Electrical | B7: Electrical | C7: Electrical
A8: Plumbing | B8: Plumbing | C8: Plumbing
A9: Barriers | B9: Barriers | C9: Barriers
A10: Fire Fighting pumps | B10: Fire Fighting pumps | C10: Fire pumps
A11: Generators | B11: Generators | C11: Generators
A12: Elevators | B12: Elevators | C12: Elevators
A13: Fire Extuinguishers | B13: Fire Extuinguishers | C13: Fire Extuinguishers
A14: CCTV | B14: CCTV | C14: CCTV
A15: Computers | B15: Computers | C15: Computers
A16: Servers | B16: Servers | C16: Servers
A17: Cell phones | B17: Cell phones | C17: Cell phones
... A23: Parking System | B23: Parking System | C23: Parking System

Sheet Asset Dep Groups
A1: Return | C1: Dep. Groups control the Dep. Method , as per BPR please consider the assets to be fully dep on the first month as a separate dep. Group
A5: Depreciation Group Code | B5: Depreciation Group Name | C5: Recovery Details (years) | D5: Debit GL | E5: Credit GL | F5: GL Book | G5: Status
A6: HVACMec | B6: HVAC/Mechanical | C6: 5 | D6: 8210-0600 | E6: 1225-0500 | F6: Accrual | G6: Depreciable
A7: Electrical | B7: Electrical | C7: 5 | D7: 8210-0600 | E7: 1225-0500 | F7: Accrual | G7: Depreciable
A8: Plumbing | B8: Plumbing | C8: 5 | D8: 8210-0600 | E8: 1225-0500 | F8: Accrual | G8: Depreciable
B9: Barriers | C9: 5 | D9: 8210-0600 | E9: 1225-0500 | F9: Accrual | G9: Depreciable
A10: Fire pumps | B10: Fire pumps | C10: 5 | D10: 8210-0600 | E10: 1225-0500 | F10: Accrual | G10: Depreciable
A11: Generators | B11: Generators | C11: 5 | D11: 8210-0600 | E11: 1225-0500 | F11: Accrual | G11: Depreciable
A12: Elevators | B12: Elevators | C12: 5 | D12: 8210-0600 | E12: 1225-0500 | F12: Accrual | G12: Depreciable
A13: FireExt | B13: Fire Extinguishers | C13: 5 | D13: 8210-0600 | E13: 1225-0500 | F13: Accrual | G13: Depreciable
A14: CCTV | B14: CCTV | C14: 5 | D14: 8210-0500 | E14: 1225-0400 | F14: Accrual | G14: Depreciable
A15: Comp | B15: Computers | C15: 3 | D15: 8210-0500 | E15: 1225-0400 | F15: Accrual | G15: Depreciable
A16: Servers | B16: Servers | C16: 3 | D16: 8210-0500 | E16: 1225-0400 | F16: Accrual | G16: Depreciable
A17: CellPh | B17: Cell phones | C17: 3 | D17: 8210-0500 | E17: 1225-0400 | F17: Accrual | G17: Depreciable
A18: IT Equip | B18: IT Equip | C18: 3 | D18: 8210-0500 | E18: 1225-0400 | F18: Accrual | G18: Depreciable
A19: F&F | B19: F&F | C19: 5 | D19: 8210-0300 | E19: 1225-0200 | F19: Accrual | G19: Depreciable
A20: Tools | B20: Tools | C20: 5 | D20: 8210-0700 | E20: 1225-0600 | F20: Accrual | G20: Depreciable
A21: LowCursy | B21: Low Current System | C21: 5 | D21: 8210-0700 | E21: 1225-0600 | F21: Accrual | G21: Depreciable
A22: Building
A23: Parking System
A24: NonDep | B24: NonDep | C24: 0 | D24: 8210-0600 | E24: 1225-0500 | G24: NonDepreciable

Sheet Asset Type
B1: Return
G2: Asset types control the default Asset account , depreciation group and also used for reporting
E3: For Asset Transactions
H4: GL Accounts
B5: Asset Type code | C5: Recovery Details (years) | D5: Asset type name | E5: Description | F5: Asset Depreciation Group | G5: Asset Code Prefix | H5: Asset Cost Account | I5: Disposition Account | J5: Accumulated Disposition | K5: Derecognition cost Account | L5: Derecognition - Acc Depr | M5: Asset Revaluation | N5: Revaluation Reserve | O5: Revaluation P&L | P5: Revaluation Surplus/Deficit
B6: HVACMec | D6: HVAC/Mechanical | E6: HVAC/Mechanical | F6: HVACMec | G6: HVACMec | H6: 1220-0500 | I6: 7260-1000 | J6: 1225-0500 | K6: 7260-1000 | L6: 1225-0500 | Q6: 8210-0200 | R6: PPE Dep - Building and Infrastructure
B7: Electrical | D7: Electrical | E7: Electrical | F7: Electrical | G7: ELE | H7: 1220-0500 | I7: 7260-1000 | J7: 1225-0500 | K7: 7260-1000 | L7: 1225-0500 | Q7: 8210-0300 | R7: PPE Dep - Furniture & Fixtures
B8: Plumbing | D8: Plumbing | E8: Plumbing | F8: Plumbing | G8: PLM | H8: 1220-0500 | I8: 7260-1000 | J8: 1225-0500 | K8: 7260-1000 | L8: 1225-0500 | Q8: 8210-0400 | R8: PPE Dep - Office Equipment
B9: Barriers | D9: Barriers | E9: Barriers | F9: Barriers | G9: BAR | H9: 1220-0500 | I9: 7260-1000 | J9: 1225-0500 | K9: 7260-1000 | L9: 1225-0500 | Q9: 8210-0500 | R9: PPE Dep - IT Hardware
B10: Fire pumps | D10: Fire pumps | E10: Fire pumps | F10: Fire pumps | G10: FRP | H10: 1220-0500 | I10: 7260-1000 | J10: 1225-0500 | K10: 7260-1000 | L10: 1225-0500 | Q10: 8210-0600 | R10: PPE Dep - Machinery & Equipment
B11: Generators | D11: Generators | E11: Generators | F11: Generators | G11: GEN | H11: 1220-0500 | I11: 7260-1000 | J11: 1225-0500 | K11: 7260-1000 | L11: 1225-0500 | Q11: 8210-0700 | R11: PPE Dep - Tools & Appliances
B12: Elevators | D12: Elevators | E12: Elevators | F12: Elevators | G12: ELV | H12: 1220-0500 | I12: 7260-1000 | J12: 1225-0500 | K12: 7260-1000 | L12: 1225-0500 | Q12: 8210-0800 | R12: PPE Dep - Motor Vehicles
B13: Fire Extuinguishers | D13: Fire Extuinguishers | E13: Fire Extuinguishers | F13: Fire Extuinguishers | G13: FRE | H13: 1220-0500 | I13: 7260-1000 | J13: 1225-0500 | K13: 7260-1000 | L13: 1225-0500 | Q13: 8210-0900 | R13: PPE Dep - Expensed assets
B14: CCTV | D14: CCTV | E14: CCTV | F14: CCTV | G14: CCV | H14: 1220-0400 | I14: 7260-1000 | J14: 1225-0400 | K14: 7260-1000 | L14: 1225-0400 | Q14: 8210-1000 | R14: PPE Dep - Other
B15: Computers | D15: Computers | E15: Computers | F15: Computers | G15: COM | H15: 1220-0400 | I15: 7260-1000 | J15: 1225-0400 | K15: 7260-1000 | L15: 1225-0400 | Q15: 8210-1400 | R15: IP Dep - Expensed Assets
B16: Servers | D16: Servers | E16: Servers | F16: Servers | G16: SER | H16: 1220-0400 | I16: 7260-1000 | J16: 1225-0400 | K16: 7260-1000 | L16: 1225-0400 | Q16: 1220-0100 | R16: PPE Cost - Building and Infrastructure
B17: Cell phones | D17: Cell phones | E17: Cell phones | F17: Cell phones | G17: PHN | H17: 1220-0400 | I17: 7260-1000 | J17: 1225-0400 | K17: 7260-1000 | L17: 1225-0400 | Q17: 1220-0200 | R17: PPE Cost - Furniture & Fixtures
... B19: F&F | D19: Furnitures and Fixtures | E19: Furnitures and Fixtures | F19: F&F | G19: FNF | H19: 1220-0200 | I19: 7260-1000 | J19: 1225-0200 | K19: 7260-1000 | L19: 1225-0200 | Q19: 1220-0400 | R19: PPE Cost - IT Hardware
B20: Building | D20: Building | E20: Building | F20: Building | G20: BUL | H20: 1220-0100 | J20: 1225-0100 | L20: 1225-0100 | Q20: 8210-0200 | R20: PPE Dep - Building and Infrastructure
B21: Parking System | D21: Parking System | E21: Parking System | F21: Parksys | G21: PSY
B24: Fan coil unit | D24: Fan coil unit | E24: Fan coil unit | F24: HVAC/Mechanical | G24: HVACMec | H24: 1220-0500 | I24: 7260-1000 | J24: 1225-0500 | K24: 7260-1000 | L24: 1225-0500
B25: Chilers | D25: Chilers | E25: Chilers | F25: HVAC/Mechanical | G25: HVACMec | H25: 1220-0500 | I25: 7260-1000 | J25: 1225-0500 | K25: 7260-1000 | L25: 1225-0500
B26: Chilled water pumps | D26: Chilled water pumps | E26: Chilled water pumps | F26: HVAC/Mechanical | G26: HVACMec | H26: 1220-0500 | I26: 7260-1000 | J26: 1225-0500 | K26: 7260-1000 | L26: 1225-0500
B27: Cooling tower | D27: Cooling tower | E27: Cooling tower | F27: HVAC/Mechanical | G27: HVACMec | H27: 1220-0500 | I27: 7260-1000 | J27: 1225-0500 | K27: 7260-1000 | L27: 1225-0500
B28: Dosing system | D28: Dosing system | E28: Dosing system | F28: HVAC/Mechanical | G28: HVACMec | H28: 1220-0500 | I28: 7260-1000 | J28: 1225-0500 | K28: 7260-1000 | L28: 1225-0500
B29: pressurization system | D29: pressurization system | E29: pressurization system | F29: HVAC/Mechanical | G29: HVACMec | H29: 1220-0500 | I29: 7260-1000 | J29: 1225-0500 | K29: 7260-1000 | L29: 1225-0500
B30: Fresh air handling unit | D30: Fresh air handling unit | E30: Fresh air handling unit | F30: HVAC/Mechanical | G30: HVACMec | H30: 1220-0500 | I30: 7260-1000 | J30: 1225-0500 | K30: 7260-1000 | L30: 1225-0500
B31: Air hauding unit | D31: Air hauding unit | E31: Air hauding unit | F31: HVAC/Mechanical | G31: HVACMec | H31: 1220-0500 | I31: 7260-1000 | J31: 1225-0500 | K31: 7260-1000 | L31: 1225-0500
B32: Life safety fan | D32: Life safety fan | E32: Life safety fan | F32: HVAC/Mechanical | G32: HVACMec | H32: 1220-0500 | I32: 7260-1000 | J32: 1225-0500 | K32: 7260-1000 | L32: 1225-0500
B33: Dx Unit | D33: Dx Unit | E33: Dx Unit | F33: HVAC/Mechanical | G33: HVACMec | H33: 1220-0500 | I33: 7260-1000 | J33: 1225-0500 | K33: 7260-1000 | L33: 1225-0500
B34: Package unit | D34: Package unit | E34: Package unit | F34: HVAC/Mechanical | G34: HVACMec | H34: 1220-0500 | I34: 7260-1000 | J34: 1225-0500 | K34: 7260-1000 | L34: 1225-0500
B35: Decoratiue unit | D35: Decoratiue unit | E35: Decoratiue unit | F35: HVAC/Mechanical | G35: HVACMec | H35: 1220-0500 | I35: 7260-1000 | J35: 1225-0500 | K35: 7260-1000 | L35: 1225-0500
... B47: Elevators | D47: Elevators | E47: Elevators | F47: Elevators | G47: ELV | H47: 1220-0500 | I47: 7260-1000 | J47: 1225-0500 | K47: 7260-1000 | L47: 1225-0500
B105: PM
B106: PM_HVAC | D106: PM_HVAC | E106: PM_HVAC/Mechanical | F106: NonDepreciable | G106: HVC | H106: 1220-0500 | I106: 7260-1000 | J106: 1225-0500 | K106: 7260-1000 | L106: 1225-0500 | Q106: 1220-0500 | R106: PPE Cost - Machinery & Equipment
B107: PM_Electrical | D107: PM_Electrical | E107: PM_Electrical | F107: NonDepreciable | G107: ELE | H107: 1220-0500 | I107: 7260-1000 | J107: 1225-0500 | K107: 7260-1000 | L107: 1225-0500 | Q107: 1220-0600 | R107: PPE Cost - Tools & Appliances
B108: PM_Plumbing | D108: PM_Plumbing | E108: Plumbing | F108: NonDepreciable | G108: PLM | H108: 1220-0500 | I108: 7260-1000 | J108: 1225-0500 | K108: 7260-1000 | L108: 1225-0500 | Q108: 1220-0700 | R108: PPE Cost - Motor Vehicles
B109: PM_Barriers | D109: PM_Barriers | E109: Barriers | F109: NonDepreciable | G109: BAR | H109: 1220-0500 | I109: 7260-1000 | J109: 1225-0500 | K109: 7260-1000 | L109: 1225-0500 | Q109: 1220-0800 | R109: PPE Cost - Expensed assets
B110: PM_Fire pumps | D110: PM_Fire pumps | E110: Fire pumps | F110: NonDepreciable | G110: FRP | H110: 1220-0500 | I110: 7260-1000 | J110: 1225-0500 | K110: 7260-1000 | L110: 1225-0500 | Q110: 1220-0900 | R110: PPE Cost - Other
B111: PM_Generators | D111: PM_Generators | E111: Generators | F111: NonDepreciable | G111: GEN | H111: 1220-0500 | I111: 7260-1000 | J111: 1225-0500 | K111: 7260-1000 | L111: 1225-0500 | Q111: 1220-9999 | R111: Total Property, Plant & Equipment - Cost
...

Sheet Asset Attachment type
A1: Return
A2: Asset Attachment types
B5: Object | C5: Attachment types
B6: Fixed Asset | C6: Warranty
B7: Fixed Asset | C7: Manuals
B8: Fixed Asset | C8: Supplier documents
B9: Fixed Asset | C9: Others

Sheet Assets Process
A1: Return
A4: They receive the full value of the whole building, including the value and cost of the all assets included in the building
A5: No Split or assets reigestered for the assets in the building
A6: FM will build the asset register for the handed over buildings and all the assets will be tagged under the nondeprciable group
A7: In case of new asset is added to the handed over building, they will be tagged under their respectvie depreciation group and deprciated as per schedule
A10: Will the building value get reduced by the value of the new added deprciated asset?
A11: The assets that are going to be under decprciated groups will be added to the system with their current value, and deprciation will be calculated from that point
A12: The value of the added assets will be deducted from the total building asset value
A13: Finance will be responsible to add and capitlize the new assets

Sheet Maintenance models
A1: Return
A3: Model | B3: In Scope (Y/N)
A4: In-house servicing | B4: Y
A5: 2. Outsourcing Model – Contractual Work | B5: Y
A6: 3. Outsourcing Model – Non‑Contractual Work | B6: Y
A7: 4. Out of Scope Work | B7: Y
A8: 5. Major WO | B8: Y
A11: Maintenance Models Overview
A13: 1. In‑House Servicing
A14: Process Step | B14: FM Team | C14: Vendor | D14: WO Status Lifecycle
A15: 1. Maintenance Request (WO) raised by any end-user under “General Maintenance” category | B15: - | C15: – | D15: Call
A16: 2. CAFM planner receives WO and updates unit, category, WO category and priority | B16: ✔️ | C16: – | D16: Call
A17: 3. CAFM Planner assigns supervisor/technicians | B17: ✔️ | C17: – | D17: Scheduled
A18: 4. Technicians visit site, identify materials required | B18: ✔️ | C18: – | D18: In Progress
A19: 5. Technicians add required materials or spare parts | B19: ✔️ | C19: – | D19: Material Required
A20: 6. Storekeeper releases the materials and quantity (Cost TBD) | B20: ✔️ | C20: – | D20: Material Released
A21: 7. Technician executes work and marks as "Ready to Close" | B21: ✔️ | C21: – | D21: Ready to Close
A22: 8. Supervisor reviews and closes work | B22: ✔️ | C22: – | D22: Work Completed
A23: Additional Statuses | D23: On-Hold, Cancelled, Request Reassignment, Reopened
A25: 2. Outsourcing Model – Contractual Work
A26: Process Step | B26: FM Team | C26: Vendor | D26: WO Status Lifecycle
A27: 1. Maintenance Request (WO) raised by any end-user under “General Maintenance” category | B27: ✔️ | C27: – | D27: Call
A28: 2. CAFM planner receives WO and updates unit, category, WO category and priority | B28: ✔️ | C28: – | D28: Scheduled
A29: 3. FM Manager/Technician tags equipment and assigns to SC Vendor | B29: ✔️ | C29: – | D29: Assigned to Vendor
A30: 4. Vendor Performs work & submits job completion report to FM | B30: – | C30: ✔️ | D30: Vendor Completed
A31: 7. FM Manager reviews work, attaches job completion report, marks WO completed | B31: ✔️ | C31: – | D31: Work Completed
A32: Additional Statuses | D32: On‑Hold, Cancelled, Reopened
A35: 3. Outsourcing Model – Non‑Contractual Work
A36: Process Step | B36: FM Team | C36: Vendor | D36: WO Status Lifecycle
A37: 1. Maintenance Request (WO) raised by any end-user under “General Maintenance” category | B37: ✔️ | C37: – | D37: Call
A38: 2. CAFM planner receives WO and updates unit, category, WO category and priority | B38: ✔️ | C38: – | D38: Scheduled
A39: 3. Supervisor/Technician goes on site and tags equipment, and get vendor quotations | B39: ✔️ | C39: – | D39: Awaiting Vendor Quotation
A40: 4. Vendor(s) submits quotation to supervisor | B40: - | C40: ✔️ | D40: Vendor Quoation Submitted
A41: 5. FM Manager/Technician selects winning vendor | B41: ✔️ | C41: – | D41: Vendor Assigned
A42: 6. Vendor Performs work & submits job completion report to FM | B42: – | C42: ✔️ | D42: Vendor Completed
A43: 7. FM Manager reviews work, attaches job completion report, marks WO completed | B43: ✔️ | C43: - | D43: Work Completed
A44: Additional Statuses | D44: On‑Hold, Cancelled, Reopened
A47: 4. Out of Scope Work
A48: Process Step | B48: FM Team | C48: Vendor | D48: WO Status Lifecycle
A49: 1. Maintenance Request (WO) raised by any end-user under “General Maintenance” category | B49: ✔️ | C49: – | D49: Call
...

Sheet Team Structure
A1: Return
A2: Team Structure
A3: Team | B3: Role Category | C3: Position
A4: Naufar | B4: Management | C4: Facility Director
C5: Project Manager
B6: Senior Level | C6: Senior Engineer
B7: Engineering | C7: FM Engineer – Electrical
C8: FM Engineer – ELV
C9: FM Engineer – Mechanical
A10: FM Service Provider | B10: Site Management/ Adminstration | C10: FM Manager
B11: Engineering | C11: FM Engineer – ELV
C12: FM Engineer – Electrical
C13: FM Engineer – HVAC & Mechanical
C14: FM Engineer – Biomedical
B15: Supervision | C15: Supervisor – HVAC
C16: Supervisor – Electrical
C17: Supervisor – Mechanical
C18: Supervisor – Civil
C19: Supervisor – Landscaping
B20: CAFM | C20: CAFM Planners
B21: Technical | C21: Technician – HVAC
C22: Technician – Electrical
C23: Technician – Mechanical
C24: Technician – Civil
C25: Technician – Landscaping
C26: Technician – ELV
B27: Support | C27: Storekeeper
B28: HSE | C28: HSE Officer
B29: Administration | C29: FM Admin – Document Controller

Sheet Employee Work slots
A1: Return
A2: Employee work slots
A4: Days of the Week
A6: Day of Week | B6: Start Time | C6: End Time
A7: all 7 days | B7: 12h00 | C7: 23h59
A15: Slot | B15: From time | C15: To Time
A16: Day shift | B16: 07-AM | C16: 07-PM
A17: Night shift | B17: 07-PM | C17: 07-AM

Sheet WO Priority
A1: Return
A2: 1 | B2: Work Order Setup
A4: 1.01 | B4: WO Priority (for configuration) | C4: Remarks | D4: Colour Preference on Tech Mobile?
A5: 1 | B5: P1 - Emergency | C5: Critical | D5: Red
A6: 2 | B6: P2 - Urgent | C6: High | D6: Orange
A7: 3 | B7: P3 - High | C7: Medium | D7: Green
A8: 4 | B8: P4 – Routine | C8: PPM | D8: Orange/Yellow
A9: 5 | B9: P5 - Low | C9: Low | D9: Blue

Sheet WO Status and Change Reason
A1: Return
A2: 1 | B2: Work Order Setup
A5: 1.02 | B5: WO Standard Status in Yardi
C6: Status | D6: Type (standard/custom) | E6: Commercial Café Status name | F6: Commercial Café Email Yes/No
C7: Call | D7: Standard | E7: General Maintenance Request
C8: Web | D8: Standard | E8: General Maintenance Request
C9: Scheduled | D9: Standard | E9: In Progress
C10: In Progress | D10: Standard | E10: In Progress
C11: Work Completed | D11: Standard | E11: Completed | F11: Yes
C12: Cancelled | D12: Standard | E12: Cancelled | F12: Yes
C13: On Hold | D13: Standard | E13: On Hold
C14: Awaiting Quotation | D14: Custom | E14: In Progress
C15: Quotation submitted | D15: Custom | E15: In Progress
C16: Quotation Approval | D16: Custom | E16: In Progress
C17: Quotaiton Approval | D17: Custom | E17: In Progress
C18: Quotation Approved | D18: Custom | E18: In Progress
C19: Procurement Review | D19: Custom | E19: In Progress
C20: Procurement Review | D20: Custom | E20: In Progress
C21: Assigned for Work | D21: Custom | E21: In Progress
C22: In Progress | D22: Custom | E22: In Progress
C23: Vendor Completed | D23: Custom | E23: Completed
C24: Vendor Onboarding | D24: Custom
A26: 1.03 | B26: WO Status Change Reason | C26: Status | D26: Reason
C27: On Hold | D27: Awaiting quotation
D28: Awaiting Approvals
D29: Awaiting FM/PM feedback
D30: Tenant/Access not available
D31: Awaiting Materials
D32: Requires Specialized Skill
D33: Material Out of stock
D34: Awaiting vendor schedule
D35: Under verification
C36: Cancelled
D37: Under Warranty
D38: Duplicate WO
C39: Request Re-assignment | D39: Requires vendor replacement

Sheet WO Matrix
A1: Return
A2: 1.04 | B2: WO Category | C2: Category | D2: AMC (Yes/No) | E2: Commercial Café Category name
C3: HVAC | D3: Yes | E3: HVAC
C4: Fire Life Safety | D4: Yes | E4: Fire Life Safety
C5: Soft Services | D5: Yes | E5: Soft Services
C6: Civil | D6: Yes | E6: Civil
C7: Electical | D7: Yes | E7: Electical
C8: Plumbing | D8: Yes | E8: Plumbing
C9: Security System | D9: No | E9: Security System
C10: Mechanical | D10: Yes | E10: Mechanical
C11: Elevator | D11: Yes | E11: Elevator & Escalator
C12: Vertical Transport | D12: No | E12: Vertical Transport
C13: LPG Systems | D13: No | E13: LPG Systems
C14: Parking Management System | D14: No | E14: Parking Management System
... C21: HOSPY | D21: Yes | E21: Laundry & Kitchen Equipments
A24: 1.05 | B24: WO Subcategory | C24: Category | D24: SubCategory | E24: Remarks
C25: WO_Category.HVAC | D25: AHU
C26: WO_Category.HVAC | D26: FCU
C27: WO_Category.HVAC | D27: VAV
C28: WO_Category.HVAC | D28: FAHU
C29: WO_Category.HVAC | D29: Cooling Tower
C30: WO_Category.HVAC | D30: Chillers
C31: WO_Category.HVAC | D31: Window AC
C32: WO_Category.HVAC | D32: Split AC
C33: WO_Category.HVAC | D33: Package Unit AC
C34: WO_Category.HVAC | D34: Spilit Duct AC
C35: WO_Category.HVAC | D35: Exhaust/Ventilation
C36: WO_Category.HVAC | D36: Heat exchanger
... C50: WO_Category.HVAC | D50: Others
C51: WO_Category.HVAC | D51: Smoke Extract Fans | E51: new added
C52: WO_Category.HVAC | D52: Humidifiers & Dehumidifiers | E52: Important for climate control in Hospitals
C53: WO_Category.HVAC | D53: UV Air Purification Systems | E53: Used in HVAC for better air quality.
C54: WO_Category.HVAC | D54: Air cuirtain
C55: WO_Category.Civil | D55: Painting
C56: WO_Category.Civil | D56: Flooring
C57: WO_Category.Civil | D57: Demolishing
C58: WO_Category.Civil | D58: Fitting
C59: WO_Category.Civil | D59: Ceiling
C60: WO_Category.Civil | D60: Carpet repairs/replacement
C61: WO_Category.Civil | D61: Keys & Locks
...

Sheet Employee Skills
A1: Return
A3: 1.11 | B3: Skills
B5: Skill code | C5: Skill name | D5: Pay amount | E5: Bill amount | F5: Property
B6: SGD | C6: Security Guard | E6: 0 | F6: .all
B7: ACC | C7: AC Craftworker | E7: 0 | F7: .all
B8: ACT | C8: AC Technician | E8: 0 | F8: .all
B9: ADRENG | C9: Agricultural Engineer | E9: 0 | F9: .all
B10: AACT | C10: Assistant AC Technician | E10: 0 | F10: .all
B11: AMC | C11: Assistant Mason Craftworker | E11: 0 | F11: .all
B12: AP | C12: Assistant Painter | E12: 0 | F12: .all
B13: AT | C13: Assistant Technician | E13: 0 | F13: .all
B14: ASPT | C14: Assistant Swimming Pool Technican | E14: 0 | F14: .all
B15: AWF | C15: Assistant Welder & Fabricator | E15: 0 | F15: .all
B16: CAHKSUP | C16: Camp Administrator & HK Supervisor | E16: 0 | F16: .all
B17: CC | C17: Carpenter Craftworker | E17: 0 | F17: .all
... B44: HKT | C44: Housekeeping teamleader | E44: 0 | F44: .all

Sheet WO Attachments Types
A1: Return
B2: WO Attachments Types
B3: Quotations
B4: Works Completion Certificates
B5: Material Delivery Note
B6: PM Service Report
B7: Incident Reports
B8: Email Approval
B9: Technical/Inspection Reports
B10: Scope of Work Form
B11: Others
B12: Third Party Sevice Report
B13: Warranty Certificate

Sheet WO SLA KPI and Due Date Default
A1: Return
B2: Work Order Setup
B4: SLA Setup (KPI) | C4: Provide for each property, Category and priority combination
B6: Property | C6: WO Category | D6: Priority | E6: Response (Any status other than Call or Work Completed) | F6: Completion (Status = Work Completed) | G6: Duration includes After Office and Weekends?
B7: Naufar | D7: P1 - Emergency | E7: 0.30 Hours | F7: 4 Hours | G7: Yes
B8: Naufar | D8: P2 - Urgent | E8: 1 Hour | F8: 12 Hours | G8: Yes
B9: Naufar | D9: P3 - High | E9: 8 Hour | F9: 48 Hours | G9: Yes
B10: Naufar | D10: P4 – Routine | E10: 48 Hour | F10: 720 Hours | G10: Yes
B11: Naufar | D11: P5 - Low | E11: 48 Hour | F11: 720 Hours | G11: Yes
B12: Populate Due date based on SLA | C12: Completion
B13: Note: WO Completion SLA is computed from WO Creation date until the date when WO status is updated to Work Completed. There is no provision to exclude time spent on interim statuses like "On Hold", Awaiting Materials etc.

Sheet WO Workflows
A1: Return
A3: Facility Management and Operations Department Roles
A4: All roles which are required for WO Workflow needs to be listed
A6: Department | B6: Role
B7: Department Manager
B8: FM Engineer
B9: FM Senior Engineer
B10: Project Manager
B11: Facility Director
B12: Assistant COO
B13: COO
B14: Supervisor
A16: FCR Proposal
A17: Workflow Step | B17: Step Type | C17: Responsible Role | D17: Next Step (Approval / Modification / Rejection)
A18: New FCR Proposal | B18: In Process | C18: Originator | D18: Department Manager Review
D19: Modification Required
D20: Approved
D21: Rejected
A22: Department Manager Review | B22: In Process | C22: Department Manager | D22: FM Engineer Review
D23: Modification Required
D24: Approved
D25: Rejected
A26: FM Engineer Review | B26: In Process | C26: FM Engineer | D26: FM Senior Engineer Review
D27: Modification Required
D29: Rejected
A30: FM Senior Engineer Review | B30: In Process | C30: FM Senior Engineer | D30: Project Manager Review
D31: Modification Required
D32: Approved
D33: Rejected
A34: Project Manager Review | B34: In Process | C34: Project Manager | D34: Facility Director Review
D35: Modification Required
D36: Approved
D37: Rejected
A38: Facility Director Review | B38: In Process | C38: Facility Director | D38: Assistant COO Review
D39: Modification Required
D40: Approved
D41: Rejected
A42: Assistant COO Review | B42: In Process | C42: Assistant COO | D42: COO Review
D43: Modification Required
D44: Approved
...

Sheet WO Config Points 
A1: Return
B2: WO Setup
B3: Overall Result Validation
B4: Cannot pass if any detail fails | C4: No
B5: Cannot pass if a work order has been created | C5: No
B6: Cannot set if any detail does not have a result | C6: No
B9: Failed Details Validation
B10: Require a note | C10: Yes
B11: Require a photo | C11: Yes
B12: Require a work order | C12: No

Sheet Inspection Process
A1: Return
A2: Inspection Process
A3: Patient Move-Out Process
A4: Step | B4: Activity | C4: Responsible Party
A5: 1 | B5: Patient moves out and returns access items | C5: GRO / Patient
A6: 2 | B6: Send move-out notification email | C6: GRO
A7: 3 | B7: Create inspection request | C7: CAFM Planner
A8: 4 | B8: Update unit status (pre-inspection) | C8: CAFM Planner
A9: 5 | B9: Perform unit inspection | C9: Inspector
A10: 6 | B10: Upload photos and notes | C10: Inspector
A11: 7 | B11: Create Work Orders for snags | C11: Inspector / CAFM Planner
A12: 8 | B12: Process out-of-scope issues | C12: CAFM Planner
A13: 9 | B13: Execute and verify work | C13: Technician
A14: 10 | B14: Update unit status (post-work) | C14: CAFM Planner
A15: 11 | B15: Notify GRO and share reports | C15: CAFM Planner
A17: Incident Recording Process
A18: Step | B18: Activity | C18: Responsible Party
A19: 1 | B19: Report incident | C19: End User
A20: 2 | B20: Create incident inspection request | C20: CAFM Planner
A21: 3 | B21: Visit site and inspect | C21: Technician
A22: 4 | B22: Create snagging Work Order | C22: Technician
A23: 5 | B23: Notify FM team | C23: CAFM Planner
A25: Utility Inspection
A26: Step | B26: Activity | C26: Responsible
A27: 1 | B27: Schedule recurring inspections | C27: CAFM Planner
A28: 2 | B28: Perform meter readings (Electricity, Water, Irrigation, TSE, Tank Levels) | C28: Technician
A29: 3 | B29: Review and report | C29: CAFM Planner

Sheet PM Statuses
A1: Return
B2: PPM Standard Status in Yardi
B4: Status | C4: Type (standard/custom)
B5: Call | C5: Standard
B6: Scheduled | C6: Standard
B7: In Progress | C7: Standard
B8: Work Completed | C8: Standard
B9: Cancelled | C9: Standard
B10: On Hold | C10: Standard
C11: Custom
C12: Custom
C13: Custom
C14: Custom
C15: Custom
C16: Custom
C17: Custom
B18: Assigned for Work | C18: Custom
B19: In Progress | C19: Custom
B22: PPM Status Change Reason
B23: Status | C23: Reason
B24: On Hold | C24: Awaiting quotation
C25: Awaiting Approvals
C26: Awaiting FM/PM feedback
C27: Tenant/Access not available
C28: Awaiting Materials
C29: Requires Specialized Skill
C30: Material Out of stock
C31: Awaiting vendor schedule
C32: Under Verification
B33: Cancelled
B34: Request Re-assignment

Sheet PPM Process 
A1: Return
B2: PPM Process
B3: Step | C3: Activity | D3: In-house Process | E3: AMC Vendor Process
B4: 1 | C4: Create Equipment Templates | D4: FM Manager creates templates including PPM checklists, frequency, and readings | E4: FM Manager creates templates including PPM checklists, frequency, and readings
B5: 2 | C5: Create Equipment Records | D5: FM Manager creates equipment records or imports via template | E5: FM Manager creates equipment records or imports via template
B6: 3 | C6: PM Scheduling | D6: PMs are automatically generated as per schedule (daily automated task after office hours) | E6: PMs are automatically generated as per schedule (daily automated task after office hours)
B7: 4 | C7: PM Assignment | D7: PMs are auto-assigned to FM Manager based on assignment rules | E7: PMs are auto-assigned to Service Provider based on assignment rules
B8: 5 | C8: Perform PM Inspection | D8: FM Manager performs PM inspection and snagging | E8: Service Provider performs PM, completes checklist, uploads photos and evidence
B9: 6 | C9: Handle In-Scope Snags | D9: FM Manager raises WO for rectification | E9: Service Provider fixes snags within service contract scope
